[2024-03-26T12:21:07.929+0000] {taskinstance.py:1956} INFO - Dependencies all met for dep_context=non-requeueable deps ti=<TaskInstance: liver_disease_pipeline.import_training_data_from_s3 manual__2024-03-26T12:21:06.367952+00:00 [queued]>
[2024-03-26T12:21:07.936+0000] {taskinstance.py:1956} INFO - Dependencies all met for dep_context=requeueable deps ti=<TaskInstance: liver_disease_pipeline.import_training_data_from_s3 manual__2024-03-26T12:21:06.367952+00:00 [queued]>
[2024-03-26T12:21:07.937+0000] {taskinstance.py:2170} INFO - Starting attempt 1 of 2
[2024-03-26T12:21:07.947+0000] {taskinstance.py:2191} INFO - Executing <Task(PythonOperator): import_training_data_from_s3> on 2024-03-26 12:21:06.367952+00:00
[2024-03-26T12:21:07.952+0000] {standard_task_runner.py:60} INFO - Started process 571 to run task
[2024-03-26T12:21:07.954+0000] {standard_task_runner.py:87} INFO - Running: ['***', 'tasks', 'run', 'liver_disease_pipeline', 'import_training_data_from_s3', 'manual__2024-03-26T12:21:06.367952+00:00', '--job-id', '56', '--raw', '--subdir', 'DAGS_FOLDER/pipeline.py', '--cfg-path', '/tmp/tmpgop7uoz6']
[2024-03-26T12:21:07.956+0000] {standard_task_runner.py:88} INFO - Job 56: Subtask import_training_data_from_s3
[2024-03-26T12:21:07.993+0000] {task_command.py:423} INFO - Running <TaskInstance: liver_disease_pipeline.import_training_data_from_s3 manual__2024-03-26T12:21:06.367952+00:00 [running]> on host b16b1960aaae
[2024-03-26T12:21:08.046+0000] {taskinstance.py:2480} INFO - Exporting env vars: AIRFLOW_CTX_DAG_EMAIL='admin@localhost.com' AIRFLOW_CTX_DAG_OWNER='***' AIRFLOW_CTX_DAG_ID='liver_disease_pipeline' AIRFLOW_CTX_TASK_ID='import_training_data_from_s3' AIRFLOW_CTX_EXECUTION_DATE='2024-03-26T12:21:06.367952+00:00' AIRFLOW_CTX_TRY_NUMBER='1' AIRFLOW_CTX_DAG_RUN_ID='manual__2024-03-26T12:21:06.367952+00:00'
[2024-03-26T12:21:08.047+0000] {logging_mixin.py:188} INFO - Error saving CSV files from S3: [Errno 2] No such file or directory: 'config.yaml'
[2024-03-26T12:21:08.048+0000] {taskinstance.py:2698} ERROR - Task failed with exception
Traceback (most recent call last):
  File "/home/airflow/.local/lib/python3.8/site-packages/airflow/models/taskinstance.py", line 433, in _execute_task
    result = execute_callable(context=context, **execute_callable_kwargs)
  File "/home/airflow/.local/lib/python3.8/site-packages/airflow/operators/python.py", line 199, in execute
    return_value = self.execute_callable()
  File "/home/airflow/.local/lib/python3.8/site-packages/airflow/operators/python.py", line 216, in execute_callable
    return self.python_callable(*self.op_args, **self.op_kwargs)
  File "/opt/airflow/dags/trainingValidation.py", line 14, in import_data
    config =read_yaml('config.yaml')
  File "/opt/airflow/dags/utils/utils.py", line 11, in read_yaml
    with open(path_to_yaml) as yaml_file:
FileNotFoundError: [Errno 2] No such file or directory: 'config.yaml'
[2024-03-26T12:21:08.062+0000] {taskinstance.py:1138} INFO - Marking task as UP_FOR_RETRY. dag_id=liver_disease_pipeline, task_id=import_training_data_from_s3, execution_date=20240326T122106, start_date=20240326T122107, end_date=20240326T122108
[2024-03-26T12:21:08.071+0000] {standard_task_runner.py:107} ERROR - Failed to execute job 56 for task import_training_data_from_s3 ([Errno 2] No such file or directory: 'config.yaml'; 571)
[2024-03-26T12:21:08.087+0000] {local_task_job_runner.py:234} INFO - Task exited with return code 1
[2024-03-26T12:21:08.106+0000] {taskinstance.py:3280} INFO - 0 downstream tasks scheduled from follow-on schedule check
