[2024-03-26T11:44:36.859+0000] {taskinstance.py:1956} INFO - Dependencies all met for dep_context=non-requeueable deps ti=<TaskInstance: liver_disease_pipeline.import_training_data_from_s3 manual__2024-03-26T11:39:33.012905+00:00 [queued]>
[2024-03-26T11:44:36.866+0000] {taskinstance.py:1956} INFO - Dependencies all met for dep_context=requeueable deps ti=<TaskInstance: liver_disease_pipeline.import_training_data_from_s3 manual__2024-03-26T11:39:33.012905+00:00 [queued]>
[2024-03-26T11:44:36.867+0000] {taskinstance.py:2170} INFO - Starting attempt 2 of 2
[2024-03-26T11:44:36.877+0000] {taskinstance.py:2191} INFO - Executing <Task(PythonOperator): import_training_data_from_s3> on 2024-03-26 11:39:33.012905+00:00
[2024-03-26T11:44:36.882+0000] {standard_task_runner.py:60} INFO - Started process 1440 to run task
[2024-03-26T11:44:36.883+0000] {standard_task_runner.py:87} INFO - Running: ['***', 'tasks', 'run', 'liver_disease_pipeline', 'import_training_data_from_s3', 'manual__2024-03-26T11:39:33.012905+00:00', '--job-id', '38', '--raw', '--subdir', 'DAGS_FOLDER/pipeline.py', '--cfg-path', '/tmp/tmpc2q0ztvw']
[2024-03-26T11:44:36.885+0000] {standard_task_runner.py:88} INFO - Job 38: Subtask import_training_data_from_s3
[2024-03-26T11:44:36.919+0000] {task_command.py:423} INFO - Running <TaskInstance: liver_disease_pipeline.import_training_data_from_s3 manual__2024-03-26T11:39:33.012905+00:00 [running]> on host bda33bc72d25
[2024-03-26T11:44:36.976+0000] {taskinstance.py:2480} INFO - Exporting env vars: AIRFLOW_CTX_DAG_EMAIL='admin@localhost.com' AIRFLOW_CTX_DAG_OWNER='***' AIRFLOW_CTX_DAG_ID='liver_disease_pipeline' AIRFLOW_CTX_TASK_ID='import_training_data_from_s3' AIRFLOW_CTX_EXECUTION_DATE='2024-03-26T11:39:33.012905+00:00' AIRFLOW_CTX_TRY_NUMBER='2' AIRFLOW_CTX_DAG_RUN_ID='manual__2024-03-26T11:39:33.012905+00:00'
[2024-03-26T11:44:36.977+0000] {logging_mixin.py:188} INFO - Error saving CSV files from S3: [Errno 2] No such file or directory: 'config.yaml'
[2024-03-26T11:44:36.978+0000] {taskinstance.py:2698} ERROR - Task failed with exception
Traceback (most recent call last):
  File "/home/airflow/.local/lib/python3.8/site-packages/airflow/models/taskinstance.py", line 433, in _execute_task
    result = execute_callable(context=context, **execute_callable_kwargs)
  File "/home/airflow/.local/lib/python3.8/site-packages/airflow/operators/python.py", line 199, in execute
    return_value = self.execute_callable()
  File "/home/airflow/.local/lib/python3.8/site-packages/airflow/operators/python.py", line 216, in execute_callable
    return self.python_callable(*self.op_args, **self.op_kwargs)
  File "/opt/airflow/dags/trainingValidation.py", line 13, in import_data
    config = read_yaml('config.yaml')
  File "/opt/airflow/dags/utils/utils.py", line 11, in read_yaml
    with open(path_to_yaml) as yaml_file:
FileNotFoundError: [Errno 2] No such file or directory: 'config.yaml'
[2024-03-26T11:44:36.992+0000] {taskinstance.py:1138} INFO - Marking task as FAILED. dag_id=liver_disease_pipeline, task_id=import_training_data_from_s3, execution_date=20240326T113933, start_date=20240326T114436, end_date=20240326T114436
[2024-03-26T11:44:37.001+0000] {standard_task_runner.py:107} ERROR - Failed to execute job 38 for task import_training_data_from_s3 ([Errno 2] No such file or directory: 'config.yaml'; 1440)
[2024-03-26T11:44:37.016+0000] {local_task_job_runner.py:234} INFO - Task exited with return code 1
[2024-03-26T11:44:37.036+0000] {taskinstance.py:3280} INFO - 0 downstream tasks scheduled from follow-on schedule check
