[2024-04-08T17:03:42.406+0000] {taskinstance.py:1956} INFO - Dependencies all met for dep_context=non-requeueable deps ti=<TaskInstance: liver_disease_pipeline_2.model_evaluator manual__2024-04-08T17:03:07.391211+00:00 [queued]>
[2024-04-08T17:03:42.414+0000] {taskinstance.py:1956} INFO - Dependencies all met for dep_context=requeueable deps ti=<TaskInstance: liver_disease_pipeline_2.model_evaluator manual__2024-04-08T17:03:07.391211+00:00 [queued]>
[2024-04-08T17:03:42.415+0000] {taskinstance.py:2170} INFO - Starting attempt 1 of 2
[2024-04-08T17:03:42.426+0000] {taskinstance.py:2191} INFO - Executing <Task(PythonOperator): model_evaluator> on 2024-04-08 17:03:07.391211+00:00
[2024-04-08T17:03:42.433+0000] {standard_task_runner.py:60} INFO - Started process 4584 to run task
[2024-04-08T17:03:42.435+0000] {standard_task_runner.py:87} INFO - Running: ['***', 'tasks', 'run', 'liver_disease_pipeline_2', 'model_evaluator', 'manual__2024-04-08T17:03:07.391211+00:00', '--job-id', '235', '--raw', '--subdir', 'DAGS_FOLDER/pipeline.py', '--cfg-path', '/tmp/tmpavxc313a']
[2024-04-08T17:03:42.437+0000] {standard_task_runner.py:88} INFO - Job 235: Subtask model_evaluator
[2024-04-08T17:03:42.473+0000] {task_command.py:423} INFO - Running <TaskInstance: liver_disease_pipeline_2.model_evaluator manual__2024-04-08T17:03:07.391211+00:00 [running]> on host 60be0e44a1a9
[2024-04-08T17:03:42.542+0000] {taskinstance.py:2480} INFO - Exporting env vars: AIRFLOW_CTX_DAG_EMAIL='admin@localhost.com' AIRFLOW_CTX_DAG_OWNER='***' AIRFLOW_CTX_DAG_ID='liver_disease_pipeline_2' AIRFLOW_CTX_TASK_ID='model_evaluator' AIRFLOW_CTX_EXECUTION_DATE='2024-04-08T17:03:07.391211+00:00' AIRFLOW_CTX_TRY_NUMBER='1' AIRFLOW_CTX_DAG_RUN_ID='manual__2024-04-08T17:03:07.391211+00:00'
[2024-04-08T17:03:42.841+0000] {connectionpool.py:824} WARNING - Retrying (JitteredRetry(total=4, connect=4, read=5, redirect=5, status=5)) after connection broken by 'NewConnectionError('<urllib3.connection.HTTPConnection object at 0x7f57391ad670>: Failed to establish a new connection: [Errno -2] Name or service not known')': /api/2.0/mlflow/runs/search
[2024-04-08T17:03:47.110+0000] {connectionpool.py:824} WARNING - Retrying (JitteredRetry(total=3, connect=3, read=5, redirect=5, status=5)) after connection broken by 'NewConnectionError('<urllib3.connection.HTTPConnection object at 0x7f573919a2e0>: Failed to establish a new connection: [Errno -2] Name or service not known')': /api/2.0/mlflow/runs/search
[2024-04-08T17:03:55.214+0000] {connectionpool.py:824} WARNING - Retrying (JitteredRetry(total=2, connect=2, read=5, redirect=5, status=5)) after connection broken by 'NewConnectionError('<urllib3.connection.HTTPConnection object at 0x7f573919ac40>: Failed to establish a new connection: [Errno -2] Name or service not known')': /api/2.0/mlflow/runs/search
[2024-04-08T17:04:10.596+0000] {connectionpool.py:824} WARNING - Retrying (JitteredRetry(total=1, connect=1, read=5, redirect=5, status=5)) after connection broken by 'NewConnectionError('<urllib3.connection.HTTPConnection object at 0x7f573919a730>: Failed to establish a new connection: [Errno -2] Name or service not known')': /api/2.0/mlflow/runs/search
[2024-04-08T17:04:42.596+0000] {connectionpool.py:824} WARNING - Retrying (JitteredRetry(total=0, connect=0, read=5, redirect=5, status=5)) after connection broken by 'NewConnectionError('<urllib3.connection.HTTPConnection object at 0x7f57391ad520>: Failed to establish a new connection: [Errno -2] Name or service not known')': /api/2.0/mlflow/runs/search
[2024-04-08T17:04:42.767+0000] {logging_mixin.py:188} INFO - Error finding model with lowest accuracy: API request to http://eec2-16-171-41-165.eu-north-1.compute.amazonaws.com:5080/api/2.0/mlflow/runs/search failed with exception HTTPConnectionPool(host='eec2-16-171-41-165.eu-north-1.compute.amazonaws.com', port=5080): Max retries exceeded with url: /api/2.0/mlflow/runs/search (Caused by NewConnectionError('<urllib3.connection.HTTPConnection object at 0x7f57391adf70>: Failed to establish a new connection: [Errno -2] Name or service not known'))
[2024-04-08T17:04:42.768+0000] {python.py:201} INFO - Done. Returned value was: None
[2024-04-08T17:04:42.776+0000] {taskinstance.py:1138} INFO - Marking task as SUCCESS. dag_id=liver_disease_pipeline_2, task_id=model_evaluator, execution_date=20240408T170307, start_date=20240408T170342, end_date=20240408T170442
[2024-04-08T17:04:43.167+0000] {local_task_job_runner.py:234} INFO - Task exited with return code 0
[2024-04-08T17:04:43.181+0000] {taskinstance.py:3280} INFO - 0 downstream tasks scheduled from follow-on schedule check
