[2024-03-26T12:30:09.810+0000] {taskinstance.py:1956} INFO - Dependencies all met for dep_context=non-requeueable deps ti=<TaskInstance: liver_disease_pipeline.download_and_load_data manual__2024-03-26T12:29:48.649817+00:00 [queued]>
[2024-03-26T12:30:09.818+0000] {taskinstance.py:1956} INFO - Dependencies all met for dep_context=requeueable deps ti=<TaskInstance: liver_disease_pipeline.download_and_load_data manual__2024-03-26T12:29:48.649817+00:00 [queued]>
[2024-03-26T12:30:09.819+0000] {taskinstance.py:2170} INFO - Starting attempt 1 of 2
[2024-03-26T12:30:09.830+0000] {taskinstance.py:2191} INFO - Executing <Task(PythonOperator): download_and_load_data> on 2024-03-26 12:29:48.649817+00:00
[2024-03-26T12:30:09.836+0000] {standard_task_runner.py:60} INFO - Started process 1555 to run task
[2024-03-26T12:30:09.838+0000] {standard_task_runner.py:87} INFO - Running: ['***', 'tasks', 'run', 'liver_disease_pipeline', 'download_and_load_data', 'manual__2024-03-26T12:29:48.649817+00:00', '--job-id', '82', '--raw', '--subdir', 'DAGS_FOLDER/pipeline.py', '--cfg-path', '/tmp/tmpmwsu5ybd']
[2024-03-26T12:30:09.839+0000] {standard_task_runner.py:88} INFO - Job 82: Subtask download_and_load_data
[2024-03-26T12:30:09.874+0000] {task_command.py:423} INFO - Running <TaskInstance: liver_disease_pipeline.download_and_load_data manual__2024-03-26T12:29:48.649817+00:00 [running]> on host b16b1960aaae
[2024-03-26T12:30:09.936+0000] {taskinstance.py:2480} INFO - Exporting env vars: AIRFLOW_CTX_DAG_EMAIL='admin@localhost.com' AIRFLOW_CTX_DAG_OWNER='***' AIRFLOW_CTX_DAG_ID='liver_disease_pipeline' AIRFLOW_CTX_TASK_ID='download_and_load_data' AIRFLOW_CTX_EXECUTION_DATE='2024-03-26T12:29:48.649817+00:00' AIRFLOW_CTX_TRY_NUMBER='1' AIRFLOW_CTX_DAG_RUN_ID='manual__2024-03-26T12:29:48.649817+00:00'
[2024-03-26T12:30:10.424+0000] {taskinstance.py:2698} ERROR - Task failed with exception
Traceback (most recent call last):
  File "/home/airflow/.local/lib/python3.8/site-packages/airflow/models/taskinstance.py", line 433, in _execute_task
    result = execute_callable(context=context, **execute_callable_kwargs)
  File "/home/airflow/.local/lib/python3.8/site-packages/airflow/operators/python.py", line 199, in execute
    return_value = self.execute_callable()
  File "/home/airflow/.local/lib/python3.8/site-packages/airflow/operators/python.py", line 216, in execute_callable
    return self.python_callable(*self.op_args, **self.op_kwargs)
  File "/opt/airflow/dags/modelTraining.py", line 18, in load_data_from_s3
    import xgboost as xgb
ModuleNotFoundError: No module named 'xgboost'
[2024-03-26T12:30:10.434+0000] {taskinstance.py:1138} INFO - Marking task as UP_FOR_RETRY. dag_id=liver_disease_pipeline, task_id=download_and_load_data, execution_date=20240326T122948, start_date=20240326T123009, end_date=20240326T123010
[2024-03-26T12:30:10.444+0000] {standard_task_runner.py:107} ERROR - Failed to execute job 82 for task download_and_load_data (No module named 'xgboost'; 1555)
[2024-03-26T12:30:10.492+0000] {local_task_job_runner.py:234} INFO - Task exited with return code 1
[2024-03-26T12:30:10.513+0000] {taskinstance.py:3280} INFO - 0 downstream tasks scheduled from follow-on schedule check
