[2024-03-26T12:22:16.491+0000] {taskinstance.py:1956} INFO - Dependencies all met for dep_context=non-requeueable deps ti=<TaskInstance: liver_disease_pipeline.import_training_data_from_s3 manual__2024-03-26T12:17:13.088716+00:00 [queued]>
[2024-03-26T12:22:16.498+0000] {taskinstance.py:1956} INFO - Dependencies all met for dep_context=requeueable deps ti=<TaskInstance: liver_disease_pipeline.import_training_data_from_s3 manual__2024-03-26T12:17:13.088716+00:00 [queued]>
[2024-03-26T12:22:16.499+0000] {taskinstance.py:2170} INFO - Starting attempt 2 of 2
[2024-03-26T12:22:16.512+0000] {taskinstance.py:2191} INFO - Executing <Task(PythonOperator): import_training_data_from_s3> on 2024-03-26 12:17:13.088716+00:00
[2024-03-26T12:22:16.518+0000] {standard_task_runner.py:60} INFO - Started process 679 to run task
[2024-03-26T12:22:16.519+0000] {standard_task_runner.py:87} INFO - Running: ['***', 'tasks', 'run', 'liver_disease_pipeline', 'import_training_data_from_s3', 'manual__2024-03-26T12:17:13.088716+00:00', '--job-id', '59', '--raw', '--subdir', 'DAGS_FOLDER/pipeline.py', '--cfg-path', '/tmp/tmp1vi9s4b7']
[2024-03-26T12:22:16.521+0000] {standard_task_runner.py:88} INFO - Job 59: Subtask import_training_data_from_s3
[2024-03-26T12:22:16.558+0000] {task_command.py:423} INFO - Running <TaskInstance: liver_disease_pipeline.import_training_data_from_s3 manual__2024-03-26T12:17:13.088716+00:00 [running]> on host b16b1960aaae
[2024-03-26T12:22:16.612+0000] {taskinstance.py:2480} INFO - Exporting env vars: AIRFLOW_CTX_DAG_EMAIL='admin@localhost.com' AIRFLOW_CTX_DAG_OWNER='***' AIRFLOW_CTX_DAG_ID='liver_disease_pipeline' AIRFLOW_CTX_TASK_ID='import_training_data_from_s3' AIRFLOW_CTX_EXECUTION_DATE='2024-03-26T12:17:13.088716+00:00' AIRFLOW_CTX_TRY_NUMBER='2' AIRFLOW_CTX_DAG_RUN_ID='manual__2024-03-26T12:17:13.088716+00:00'
[2024-03-26T12:22:16.614+0000] {logging_mixin.py:188} INFO - Error saving CSV files from S3: [Errno 2] No such file or directory: 'config.yaml'
[2024-03-26T12:22:16.614+0000] {taskinstance.py:2698} ERROR - Task failed with exception
Traceback (most recent call last):
  File "/home/airflow/.local/lib/python3.8/site-packages/airflow/models/taskinstance.py", line 433, in _execute_task
    result = execute_callable(context=context, **execute_callable_kwargs)
  File "/home/airflow/.local/lib/python3.8/site-packages/airflow/operators/python.py", line 199, in execute
    return_value = self.execute_callable()
  File "/home/airflow/.local/lib/python3.8/site-packages/airflow/operators/python.py", line 216, in execute_callable
    return self.python_callable(*self.op_args, **self.op_kwargs)
  File "/opt/airflow/dags/trainingValidation.py", line 14, in import_data
    config =read_yaml('config.yaml')
  File "/opt/airflow/dags/utils/utils.py", line 11, in read_yaml
    with open(path_to_yaml) as yaml_file:
FileNotFoundError: [Errno 2] No such file or directory: 'config.yaml'
[2024-03-26T12:22:16.629+0000] {taskinstance.py:1138} INFO - Marking task as FAILED. dag_id=liver_disease_pipeline, task_id=import_training_data_from_s3, execution_date=20240326T121713, start_date=20240326T122216, end_date=20240326T122216
[2024-03-26T12:22:16.638+0000] {standard_task_runner.py:107} ERROR - Failed to execute job 59 for task import_training_data_from_s3 ([Errno 2] No such file or directory: 'config.yaml'; 679)
[2024-03-26T12:22:16.653+0000] {local_task_job_runner.py:234} INFO - Task exited with return code 1
[2024-03-26T12:22:16.671+0000] {taskinstance.py:3280} INFO - 0 downstream tasks scheduled from follow-on schedule check
