[2024-03-26T11:53:44.706+0000] {taskinstance.py:1956} INFO - Dependencies all met for dep_context=non-requeueable deps ti=<TaskInstance: liver_disease_pipeline.import_training_data_from_s3 manual__2024-03-26T11:48:41.232468+00:00 [queued]>
[2024-03-26T11:53:44.713+0000] {taskinstance.py:1956} INFO - Dependencies all met for dep_context=requeueable deps ti=<TaskInstance: liver_disease_pipeline.import_training_data_from_s3 manual__2024-03-26T11:48:41.232468+00:00 [queued]>
[2024-03-26T11:53:44.714+0000] {taskinstance.py:2170} INFO - Starting attempt 2 of 2
[2024-03-26T11:53:44.725+0000] {taskinstance.py:2191} INFO - Executing <Task(PythonOperator): import_training_data_from_s3> on 2024-03-26 11:48:41.232468+00:00
[2024-03-26T11:53:44.733+0000] {standard_task_runner.py:60} INFO - Started process 2034 to run task
[2024-03-26T11:53:44.735+0000] {standard_task_runner.py:87} INFO - Running: ['***', 'tasks', 'run', 'liver_disease_pipeline', 'import_training_data_from_s3', 'manual__2024-03-26T11:48:41.232468+00:00', '--job-id', '44', '--raw', '--subdir', 'DAGS_FOLDER/pipeline.py', '--cfg-path', '/tmp/tmpvh5jt82d']
[2024-03-26T11:53:44.736+0000] {standard_task_runner.py:88} INFO - Job 44: Subtask import_training_data_from_s3
[2024-03-26T11:53:44.774+0000] {task_command.py:423} INFO - Running <TaskInstance: liver_disease_pipeline.import_training_data_from_s3 manual__2024-03-26T11:48:41.232468+00:00 [running]> on host bda33bc72d25
[2024-03-26T11:53:44.828+0000] {taskinstance.py:2480} INFO - Exporting env vars: AIRFLOW_CTX_DAG_EMAIL='admin@localhost.com' AIRFLOW_CTX_DAG_OWNER='***' AIRFLOW_CTX_DAG_ID='liver_disease_pipeline' AIRFLOW_CTX_TASK_ID='import_training_data_from_s3' AIRFLOW_CTX_EXECUTION_DATE='2024-03-26T11:48:41.232468+00:00' AIRFLOW_CTX_TRY_NUMBER='2' AIRFLOW_CTX_DAG_RUN_ID='manual__2024-03-26T11:48:41.232468+00:00'
[2024-03-26T11:53:44.830+0000] {logging_mixin.py:188} INFO - Error saving CSV files from S3: [Errno 2] No such file or directory: 'config.yaml'
[2024-03-26T11:53:44.830+0000] {taskinstance.py:2698} ERROR - Task failed with exception
Traceback (most recent call last):
  File "/home/airflow/.local/lib/python3.8/site-packages/airflow/models/taskinstance.py", line 433, in _execute_task
    result = execute_callable(context=context, **execute_callable_kwargs)
  File "/home/airflow/.local/lib/python3.8/site-packages/airflow/operators/python.py", line 199, in execute
    return_value = self.execute_callable()
  File "/home/airflow/.local/lib/python3.8/site-packages/airflow/operators/python.py", line 216, in execute_callable
    return self.python_callable(*self.op_args, **self.op_kwargs)
  File "/opt/airflow/dags/trainingValidation.py", line 13, in import_data
    config = read_yaml('config.yaml')
  File "/opt/airflow/dags/utils/utils.py", line 11, in read_yaml
    with open(path_to_yaml) as yaml_file:
FileNotFoundError: [Errno 2] No such file or directory: 'config.yaml'
[2024-03-26T11:53:44.844+0000] {taskinstance.py:1138} INFO - Marking task as FAILED. dag_id=liver_disease_pipeline, task_id=import_training_data_from_s3, execution_date=20240326T114841, start_date=20240326T115344, end_date=20240326T115344
[2024-03-26T11:53:44.853+0000] {standard_task_runner.py:107} ERROR - Failed to execute job 44 for task import_training_data_from_s3 ([Errno 2] No such file or directory: 'config.yaml'; 2034)
[2024-03-26T11:53:44.868+0000] {local_task_job_runner.py:234} INFO - Task exited with return code 1
[2024-03-26T11:53:44.886+0000] {taskinstance.py:3280} INFO - 0 downstream tasks scheduled from follow-on schedule check
