[2024-04-08T16:51:50.560+0000] {taskinstance.py:1956} INFO - Dependencies all met for dep_context=non-requeueable deps ti=<TaskInstance: liver_disease_pipeline_2.model_evaluator manual__2024-04-08T16:51:13.852434+00:00 [queued]>
[2024-04-08T16:51:50.568+0000] {taskinstance.py:1956} INFO - Dependencies all met for dep_context=requeueable deps ti=<TaskInstance: liver_disease_pipeline_2.model_evaluator manual__2024-04-08T16:51:13.852434+00:00 [queued]>
[2024-04-08T16:51:50.568+0000] {taskinstance.py:2170} INFO - Starting attempt 1 of 2
[2024-04-08T16:51:50.580+0000] {taskinstance.py:2191} INFO - Executing <Task(PythonOperator): model_evaluator> on 2024-04-08 16:51:13.852434+00:00
[2024-04-08T16:51:50.586+0000] {standard_task_runner.py:60} INFO - Started process 3383 to run task
[2024-04-08T16:51:50.588+0000] {standard_task_runner.py:87} INFO - Running: ['***', 'tasks', 'run', 'liver_disease_pipeline_2', 'model_evaluator', 'manual__2024-04-08T16:51:13.852434+00:00', '--job-id', '227', '--raw', '--subdir', 'DAGS_FOLDER/pipeline.py', '--cfg-path', '/tmp/tmp_1gvyofo']
[2024-04-08T16:51:50.590+0000] {standard_task_runner.py:88} INFO - Job 227: Subtask model_evaluator
[2024-04-08T16:51:50.627+0000] {task_command.py:423} INFO - Running <TaskInstance: liver_disease_pipeline_2.model_evaluator manual__2024-04-08T16:51:13.852434+00:00 [running]> on host 60be0e44a1a9
[2024-04-08T16:51:50.693+0000] {taskinstance.py:2480} INFO - Exporting env vars: AIRFLOW_CTX_DAG_EMAIL='admin@localhost.com' AIRFLOW_CTX_DAG_OWNER='***' AIRFLOW_CTX_DAG_ID='liver_disease_pipeline_2' AIRFLOW_CTX_TASK_ID='model_evaluator' AIRFLOW_CTX_EXECUTION_DATE='2024-04-08T16:51:13.852434+00:00' AIRFLOW_CTX_TRY_NUMBER='1' AIRFLOW_CTX_DAG_RUN_ID='manual__2024-04-08T16:51:13.852434+00:00'
[2024-04-08T16:51:50.944+0000] {connectionpool.py:824} WARNING - Retrying (JitteredRetry(total=4, connect=4, read=5, redirect=5, status=5)) after connection broken by 'NewConnectionError('<urllib3.connection.HTTPConnection object at 0x7f5739107af0>: Failed to establish a new connection: [Errno -2] Name or service not known')': /api/2.0/mlflow/runs/search
[2024-04-08T16:51:55.488+0000] {connectionpool.py:824} WARNING - Retrying (JitteredRetry(total=3, connect=3, read=5, redirect=5, status=5)) after connection broken by 'NewConnectionError('<urllib3.connection.HTTPConnection object at 0x7f5739107f10>: Failed to establish a new connection: [Errno -2] Name or service not known')': /api/2.0/mlflow/runs/search
[2024-04-08T16:52:03.953+0000] {connectionpool.py:824} WARNING - Retrying (JitteredRetry(total=2, connect=2, read=5, redirect=5, status=5)) after connection broken by 'NewConnectionError('<urllib3.connection.HTTPConnection object at 0x7f57391074c0>: Failed to establish a new connection: [Errno -2] Name or service not known')': /api/2.0/mlflow/runs/search
[2024-04-08T16:52:19.363+0000] {connectionpool.py:824} WARNING - Retrying (JitteredRetry(total=1, connect=1, read=5, redirect=5, status=5)) after connection broken by 'NewConnectionError('<urllib3.connection.HTTPConnection object at 0x7f57391074f0>: Failed to establish a new connection: [Errno -2] Name or service not known')': /api/2.0/mlflow/runs/search
[2024-04-08T16:52:50.926+0000] {connectionpool.py:824} WARNING - Retrying (JitteredRetry(total=0, connect=0, read=5, redirect=5, status=5)) after connection broken by 'NewConnectionError('<urllib3.connection.HTTPConnection object at 0x7f5739107be0>: Failed to establish a new connection: [Errno -2] Name or service not known')': /api/2.0/mlflow/runs/search
[2024-04-08T16:52:51.136+0000] {logging_mixin.py:188} INFO - Error finding model with lowest accuracy: API request to http://eec2-16-171-41-165.eu-north-1.compute.amazonaws.com:5080/api/2.0/mlflow/runs/search failed with exception HTTPConnectionPool(host='eec2-16-171-41-165.eu-north-1.compute.amazonaws.com', port=5080): Max retries exceeded with url: /api/2.0/mlflow/runs/search (Caused by NewConnectionError('<urllib3.connection.HTTPConnection object at 0x7f5739164100>: Failed to establish a new connection: [Errno -2] Name or service not known'))
[2024-04-08T16:52:51.136+0000] {python.py:201} INFO - Done. Returned value was: None
[2024-04-08T16:52:52.986+0000] {taskinstance.py:1138} INFO - Marking task as SUCCESS. dag_id=liver_disease_pipeline_2, task_id=model_evaluator, execution_date=20240408T165113, start_date=20240408T165150, end_date=20240408T165252
[2024-04-08T16:52:53.175+0000] {local_task_job_runner.py:234} INFO - Task exited with return code 0
[2024-04-08T16:52:53.190+0000] {taskinstance.py:3280} INFO - 0 downstream tasks scheduled from follow-on schedule check
