[2024-03-26T12:27:36.860+0000] {taskinstance.py:1956} INFO - Dependencies all met for dep_context=non-requeueable deps ti=<TaskInstance: liver_disease_pipeline.validate_data manual__2024-03-26T12:27:27.883060+00:00 [queued]>
[2024-03-26T12:27:36.867+0000] {taskinstance.py:1956} INFO - Dependencies all met for dep_context=requeueable deps ti=<TaskInstance: liver_disease_pipeline.validate_data manual__2024-03-26T12:27:27.883060+00:00 [queued]>
[2024-03-26T12:27:36.868+0000] {taskinstance.py:2170} INFO - Starting attempt 1 of 2
[2024-03-26T12:27:36.878+0000] {taskinstance.py:2191} INFO - Executing <Task(PythonOperator): validate_data> on 2024-03-26 12:27:27.883060+00:00
[2024-03-26T12:27:36.883+0000] {standard_task_runner.py:60} INFO - Started process 1185 to run task
[2024-03-26T12:27:36.884+0000] {standard_task_runner.py:87} INFO - Running: ['***', 'tasks', 'run', 'liver_disease_pipeline', 'validate_data', 'manual__2024-03-26T12:27:27.883060+00:00', '--job-id', '70', '--raw', '--subdir', 'DAGS_FOLDER/pipeline.py', '--cfg-path', '/tmp/tmpgjby5s4b']
[2024-03-26T12:27:36.886+0000] {standard_task_runner.py:88} INFO - Job 70: Subtask validate_data
[2024-03-26T12:27:36.918+0000] {task_command.py:423} INFO - Running <TaskInstance: liver_disease_pipeline.validate_data manual__2024-03-26T12:27:27.883060+00:00 [running]> on host b16b1960aaae
[2024-03-26T12:27:36.979+0000] {taskinstance.py:2480} INFO - Exporting env vars: AIRFLOW_CTX_DAG_EMAIL='admin@localhost.com' AIRFLOW_CTX_DAG_OWNER='***' AIRFLOW_CTX_DAG_ID='liver_disease_pipeline' AIRFLOW_CTX_TASK_ID='validate_data' AIRFLOW_CTX_EXECUTION_DATE='2024-03-26T12:27:27.883060+00:00' AIRFLOW_CTX_TRY_NUMBER='1' AIRFLOW_CTX_DAG_RUN_ID='manual__2024-03-26T12:27:27.883060+00:00'
[2024-03-26T12:27:36.985+0000] {logging_mixin.py:188} INFO - Error validating CSV files: [Errno 2] No such file or directory: 'config.yaml'
[2024-03-26T12:27:36.986+0000] {taskinstance.py:2698} ERROR - Task failed with exception
Traceback (most recent call last):
  File "/home/airflow/.local/lib/python3.8/site-packages/airflow/models/taskinstance.py", line 433, in _execute_task
    result = execute_callable(context=context, **execute_callable_kwargs)
  File "/home/airflow/.local/lib/python3.8/site-packages/airflow/operators/python.py", line 199, in execute
    return_value = self.execute_callable()
  File "/home/airflow/.local/lib/python3.8/site-packages/airflow/operators/python.py", line 216, in execute_callable
    return self.python_callable(*self.op_args, **self.op_kwargs)
  File "/opt/airflow/dags/trainingValidation.py", line 77, in validate_data
    config = read_yaml('config.yaml')
  File "/opt/airflow/dags/utils/utils.py", line 11, in read_yaml
    with open(path_to_yaml) as yaml_file:
FileNotFoundError: [Errno 2] No such file or directory: 'config.yaml'
[2024-03-26T12:27:37.000+0000] {taskinstance.py:1138} INFO - Marking task as UP_FOR_RETRY. dag_id=liver_disease_pipeline, task_id=validate_data, execution_date=20240326T122727, start_date=20240326T122736, end_date=20240326T122737
[2024-03-26T12:27:37.009+0000] {standard_task_runner.py:107} ERROR - Failed to execute job 70 for task validate_data ([Errno 2] No such file or directory: 'config.yaml'; 1185)
[2024-03-26T12:27:37.017+0000] {local_task_job_runner.py:234} INFO - Task exited with return code 1
[2024-03-26T12:27:37.040+0000] {taskinstance.py:3280} INFO - 0 downstream tasks scheduled from follow-on schedule check
