[2024-04-08T16:21:58.773+0000] {taskinstance.py:1956} INFO - Dependencies all met for dep_context=non-requeueable deps ti=<TaskInstance: liver_disease_pipeline_2.model_evaluator scheduled__2024-04-07T00:00:00+00:00 [queued]>
[2024-04-08T16:21:58.781+0000] {taskinstance.py:1956} INFO - Dependencies all met for dep_context=requeueable deps ti=<TaskInstance: liver_disease_pipeline_2.model_evaluator scheduled__2024-04-07T00:00:00+00:00 [queued]>
[2024-04-08T16:21:58.782+0000] {taskinstance.py:2170} INFO - Starting attempt 1 of 2
[2024-04-08T16:21:58.795+0000] {taskinstance.py:2191} INFO - Executing <Task(PythonOperator): model_evaluator> on 2024-04-07 00:00:00+00:00
[2024-04-08T16:21:58.801+0000] {standard_task_runner.py:60} INFO - Started process 425 to run task
[2024-04-08T16:21:58.803+0000] {standard_task_runner.py:87} INFO - Running: ['***', 'tasks', 'run', 'liver_disease_pipeline_2', 'model_evaluator', 'scheduled__2024-04-07T00:00:00+00:00', '--job-id', '211', '--raw', '--subdir', 'DAGS_FOLDER/pipeline.py', '--cfg-path', '/tmp/tmp4txel21n']
[2024-04-08T16:21:58.805+0000] {standard_task_runner.py:88} INFO - Job 211: Subtask model_evaluator
[2024-04-08T16:21:58.848+0000] {task_command.py:423} INFO - Running <TaskInstance: liver_disease_pipeline_2.model_evaluator scheduled__2024-04-07T00:00:00+00:00 [running]> on host 60be0e44a1a9
[2024-04-08T16:21:58.908+0000] {taskinstance.py:2480} INFO - Exporting env vars: AIRFLOW_CTX_DAG_EMAIL='admin@localhost.com' AIRFLOW_CTX_DAG_OWNER='***' AIRFLOW_CTX_DAG_ID='liver_disease_pipeline_2' AIRFLOW_CTX_TASK_ID='model_evaluator' AIRFLOW_CTX_EXECUTION_DATE='2024-04-07T00:00:00+00:00' AIRFLOW_CTX_TRY_NUMBER='1' AIRFLOW_CTX_DAG_RUN_ID='scheduled__2024-04-07T00:00:00+00:00'
[2024-04-08T16:21:59.221+0000] {connectionpool.py:824} WARNING - Retrying (JitteredRetry(total=4, connect=4, read=5, redirect=5, status=5)) after connection broken by 'NewConnectionError('<urllib3.connection.HTTPConnection object at 0x7f573910c790>: Failed to establish a new connection: [Errno -2] Name or service not known')': /api/2.0/mlflow/runs/search
[2024-04-08T16:22:03.327+0000] {connectionpool.py:824} WARNING - Retrying (JitteredRetry(total=3, connect=3, read=5, redirect=5, status=5)) after connection broken by 'NewConnectionError('<urllib3.connection.HTTPConnection object at 0x7f573910c3a0>: Failed to establish a new connection: [Errno -2] Name or service not known')': /api/2.0/mlflow/runs/search
[2024-04-08T16:22:10.688+0000] {connectionpool.py:824} WARNING - Retrying (JitteredRetry(total=2, connect=2, read=5, redirect=5, status=5)) after connection broken by 'NewConnectionError('<urllib3.connection.HTTPConnection object at 0x7f573910c250>: Failed to establish a new connection: [Errno -2] Name or service not known')': /api/2.0/mlflow/runs/search
[2024-04-08T16:22:27.379+0000] {connectionpool.py:824} WARNING - Retrying (JitteredRetry(total=1, connect=1, read=5, redirect=5, status=5)) after connection broken by 'NewConnectionError('<urllib3.connection.HTTPConnection object at 0x7f573910c100>: Failed to establish a new connection: [Errno -2] Name or service not known')': /api/2.0/mlflow/runs/search
[2024-04-08T16:22:59.088+0000] {connectionpool.py:824} WARNING - Retrying (JitteredRetry(total=0, connect=0, read=5, redirect=5, status=5)) after connection broken by 'NewConnectionError('<urllib3.connection.HTTPConnection object at 0x7f57391597c0>: Failed to establish a new connection: [Errno -2] Name or service not known')': /api/2.0/mlflow/runs/search
[2024-04-08T16:22:59.284+0000] {logging_mixin.py:188} INFO - Error finding model with lowest accuracy: API request to http://eec2-16-171-41-165.eu-north-1.compute.amazonaws.com:5080/api/2.0/mlflow/runs/search failed with exception HTTPConnectionPool(host='eec2-16-171-41-165.eu-north-1.compute.amazonaws.com', port=5080): Max retries exceeded with url: /api/2.0/mlflow/runs/search (Caused by NewConnectionError('<urllib3.connection.HTTPConnection object at 0x7f57391590d0>: Failed to establish a new connection: [Errno -2] Name or service not known'))
[2024-04-08T16:22:59.284+0000] {python.py:201} INFO - Done. Returned value was: None
[2024-04-08T16:23:00.626+0000] {taskinstance.py:1138} INFO - Marking task as SUCCESS. dag_id=liver_disease_pipeline_2, task_id=model_evaluator, execution_date=20240407T000000, start_date=20240408T162158, end_date=20240408T162300
[2024-04-08T16:23:00.795+0000] {local_task_job_runner.py:234} INFO - Task exited with return code 0
[2024-04-08T16:23:00.811+0000] {taskinstance.py:3280} INFO - 0 downstream tasks scheduled from follow-on schedule check
